Workbook

Sheet Dienstplan
A1: Dienstplan 2027
A3: Januar
A4: KW | B4: 53 | E4: 1 | L4: 2 | S4: 3 | Z4: 4
A5: Tag | B5: 1 | C5: 2 | D5: 3 | E5: 4 | F5: 5 | G5: 6 | H5: 7 | I5: 8 | J5: 9 | K5: 10 | L5: 11 | M5: 12 | N5: 13 | O5: 14 | P5: 15 | Q5: 16 | R5: 17 | S5: 18 | T5: 19 | U5: 20 | V5: 21 | W5: 22 | X5: 23 | Y5: 24 | Z5: 25 | AA5: 26 | AB5: 27 | AC5: 28 | AD5: 29 | AE5: 30 | AF5: 31
A6: WT | B6: Fr | C6: Sa | D6: So | E6: Mo | F6: Di | G6: Mi | H6: Do | I6: Fr | J6: Sa | K6: So | L6: Mo | M6: Di | N6: Mi | O6: Do | P6: Fr | Q6: Sa | R6: So | S6: Mo | T6: Di | U6: Mi | V6: Do | W6: Fr | X6: Sa | Y6: So | Z6: Mo | AA6: Di | AB6: Mi | AC6: Do | AD6: Fr | AE6: Sa | AF6: So
A7: Breig
A8: Siebert
A9: Jochim
A10: Wunsch
A11: Göpfrich
A12: Zeller
A13: Behrendt
A14: Krempl
A15: Putschler
A16: Kunz
A17: Schmidt
A18: Radimersky
A19: Besetzung | E19: =IF(AND(COUNTIF(E7:E18,"FI")>0,COUNTIF(E7:E18,"SI")>0,COUNTIF(E7:E18,"NI")>0),"","!") | F19: =IF(AND(COUNTIF(F7:F18,"FI")>0,COUNTIF(F7:F18,"SI")>0,COUNTIF(F7:F18,"NI")>0),"","!") | H19: =IF(AND(COUNTIF(H7:H18,"FI")>0,COUNTIF(H7:H18,"SI")>0,COUNTIF(H7:H18,"NI")>0),"","!") | I19: =IF(AND(COUNTIF(I7:I18,"FI")>0,COUNTIF(I7:I18,"SI")>0),"","!") | L19: =IF(AND(COUNTIF(L7:L18,"FI")>0,COUNTIF(L7:L18,"SI")>0,COUNTIF(L7:L18,"NI")>0),"","!") | M19: =IF(AND(COUNTIF(M7:M18,"FI")>0,COUNTIF(M7:M18,"SI")>0,COUNTIF(M7:M18,"NI")>0),"","!") | N19: =IF(AND(COUNTIF(N7:N18,"FI")>0,COUNTIF(N7:N18,"SI")>0,COUNTIF(N7:N18,"NI")>0),"","!") | O19: =IF(AND(COUNTIF(O7:O18,"FI")>0,COUNTIF(O7:O18,"SI")>0,COUNTIF(O7:O18,"NI")>0),"","!") | P19: =IF(AND(COUNTIF(P7:P18,"FI")>0,COUNTIF(P7:P18,"SI")>0),"","!") | S19: =IF(AND(COUNTIF(S7:S18,"FI")>0,COUNTIF(S7:S18,"SI")>0,COUNTIF(S7:S18,"NI")>0),"","!") | T19: =IF(AND(COUNTIF(T7:T18,"FI")>0,COUNTIF(T7:T18,"SI")>0,COUNTIF(T7:T18,"NI")>0),"","!") | U19: =IF(AND(COUNTIF(U7:U18,"FI")>0,COUNTIF(U7:U18,"SI")>0,COUNTIF(U7:U18,"NI")>0),"","!") | V19: =IF(AND(COUNTIF(V7:V18,"FI")>0,COUNTIF(V7:V18,"SI")>0,COUNTIF(V7:V18,"NI")>0),"","!") | W19: =IF(AND(COUNTIF(W7:W18,"FI")>0,COUNTIF(W7:W18,"SI")>0),"","!") | Z19: =IF(AND(COUNTIF(Z7:Z18,"FI")>0,COUNTIF(Z7:Z18,"SI")>0,COUNTIF(Z7:Z18,"NI")>0),"","!") | AA19: =IF(AND(COUNTIF(AA7:AA18,"FI")>0,COUNTIF(AA7:AA18,"SI")>0,COUNTIF(AA7:AA18,"NI")>0),"","!") | AB19: =IF(AND(COUNTIF(AB7:AB18,"FI")>0,COUNTIF(AB7:AB18,"SI")>0,COUNTIF(AB7:AB18,"NI")>0),"","!") | AC19: =IF(AND(COUNTIF(AC7:AC18,"FI")>0,COUNTIF(AC7:AC18,"SI")>0,COUNTIF(AC7:AC18,"NI")>0),"","!") | AD19: =IF(AND(COUNTIF(AD7:AD18,"FI")>0,COUNTIF(AD7:AD18,"SI")>0),"","!")
P21: Faschingsferien
A22: Februar
A23: KW | B23: 5 | I23: 6 | P23: 7 | W23: 8
A24: Tag | B24: 1 | C24: 2 | D24: 3 | E24: 4 | F24: 5 | G24: 6 | H24: 7 | I24: 8 | J24: 9 | K24: 10 | L24: 11 | M24: 12 | N24: 13 | O24: 14 | P24: 15 | Q24: 16 | R24: 17 | S24: 18 | T24: 19 | U24: 20 | V24: 21 | W24: 22 | X24: 23 | Y24: 24 | Z24: 25 | AA24: 26 | AB24: 27 | AC24: 28
A25: WT | B25: Mo | C25: Di | D25: Mi | E25: Do | F25: Fr | G25: Sa | H25: So | I25: Mo | J25: Di | K25: Mi | L25: Do | M25: Fr | N25: Sa | O25: So | P25: Mo | Q25: Di | R25: Mi | S25: Do | T25: Fr | U25: Sa | V25: So | W25: Mo | X25: Di | Y25: Mi | Z25: Do | AA25: Fr | AB25: Sa | AC25: So
A26: Breig
A27: Siebert
A28: Jochim
A29: Wunsch
A30: Göpfrich
A31: Zeller
A32: Behrendt
A33: Krempl
A34: Putschler
A35: Kunz
A36: Schmidt
A37: Radimersky
A38: Besetzung | B38: =IF(AND(COUNTIF(B26:B37,"FI")>0,COUNTIF(B26:B37,"SI")>0,COUNTIF(B26:B37,"NI")>0),"","!") | C38: =IF(AND(COUNTIF(C26:C37,"FI")>0,COUNTIF(C26:C37,"SI")>0,COUNTIF(C26:C37,"NI")>0),"","!") | D38: =IF(AND(COUNTIF(D26:D37,"FI")>0,COUNTIF(D26:D37,"SI")>0,COUNTIF(D26:D37,"NI")>0),"","!") | E38: =IF(AND(COUNTIF(E26:E37,"FI")>0,COUNTIF(E26:E37,"SI")>0,COUNTIF(E26:E37,"NI")>0),"","!") | F38: =IF(AND(COUNTIF(F26:F37,"FI")>0,COUNTIF(F26:F37,"SI")>0),"","!") | I38: =IF(AND(COUNTIF(I26:I37,"FI")>0,COUNTIF(I26:I37,"SI")>0,COUNTIF(I26:I37,"NI")>0),"","!") | J38: =IF(AND(COUNTIF(J26:J37,"FI")>0,COUNTIF(J26:J37,"SI")>0,COUNTIF(J26:J37,"NI")>0),"","!") | K38: =IF(AND(COUNTIF(K26:K37,"FI")>0,COUNTIF(K26:K37,"SI")>0,COUNTIF(K26:K37,"NI")>0),"","!") | L38: =IF(AND(COUNTIF(L26:L37,"FI")>0,COUNTIF(L26:L37,"SI")>0,COUNTIF(L26:L37,"NI")>0),"","!") | M38: =IF(AND(COUNTIF(M26:M37,"FI")>0,COUNTIF(M26:M37,"SI")>0),"","!") | P38: =IF(AND(COUNTIF(P26:P37,"FI")>0,COUNTIF(P26:P37,"SI")>0,COUNTIF(P26:P37,"NI")>0),"","!") | Q38: =IF(AND(COUNTIF(Q26:Q37,"FI")>0,COUNTIF(Q26:Q37,"SI")>0,COUNTIF(Q26:Q37,"NI")>0),"","!") | R38: =IF(AND(COUNTIF(R26:R37,"FI")>0,COUNTIF(R26:R37,"SI")>0,COUNTIF(R26:R37,"NI")>0),"","!") | S38: =IF(AND(COUNTIF(S26:S37,"FI")>0,COUNTIF(S26:S37,"SI")>0,COUNTIF(S26:S37,"NI")>0),"","!") | T38: =IF(AND(COUNTIF(T26:T37,"FI")>0,COUNTIF(T26:T37,"SI")>0),"","!") | W38: =IF(AND(COUNTIF(W26:W37,"FI")>0,COUNTIF(W26:W37,"SI")>0,COUNTIF(W26:W37,"NI")>0),"","!") | X38: =IF(AND(COUNTIF(X26:X37,"FI")>0,COUNTIF(X26:X37,"SI")>0,COUNTIF(X26:X37,"NI")>0),"","!") | Y38: =IF(AND(COUNTIF(Y26:Y37,"FI")>0,COUNTIF(Y26:Y37,"SI")>0,COUNTIF(Y26:Y37,"NI")>0),"","!") | Z38: =IF(AND(COUNTIF(Z26:Z37,"FI")>0,COUNTIF(Z26:Z37,"SI")>0,COUNTIF(Z26:Z37,"NI")>0),"","!") | AA38: =IF(AND(COUNTIF(AA26:AA37,"FI")>0,COUNTIF(AA26:AA37,"SI")>0),"","!")
AB40: Osterferien
A41: März
A42: KW | B42: 9 | I42: 10 | P42: 11 | W42: 12 | AD42: 13
A43: Tag | B43: 1 | C43: 2 | D43: 3 | E43: 4 | F43: 5 | G43: 6 | H43: 7 | I43: 8 | J43: 9 | K43: 10 | L43: 11 | M43: 12 | N43: 13 | O43: 14 | P43: 15 | Q43: 16 | R43: 17 | S43: 18 | T43: 19 | U43: 20 | V43: 21 | W43: 22 | X43: 23 | Y43: 24 | Z43: 25 | AA43: 26 | AB43: 27 | AC43: 28 | AD43: 29 | AE43: 30 | AF43: 31
...

Sheet Januar
A1: Dienstplan Januar 2027 | AC1: AT: 19 Sa: 5
A3: Tag | B3: 1 | C3: 2 | D3: 3 | E3: 4 | F3: 5 | G3: 6 | H3: 7 | I3: 8 | J3: 9 | K3: 10 | L3: 11 | M3: 12 | N3: 13 | O3: 14 | P3: 15 | Q3: 16 | R3: 17 | S3: 18 | T3: 19 | U3: 20 | V3: 21 | W3: 22 | X3: 23 | Y3: 24 | Z3: 25 | AA3: 26 | AB3: 27 | AC3: 28 | AD3: 29 | AE3: 30 | AF3: 31
A4: WT | B4: Fr | C4: Sa | D4: So | E4: Mo | F4: Di | G4: Mi | H4: Do | I4: Fr | J4: Sa | K4: So | L4: Mo | M4: Di | N4: Mi | O4: Do | P4: Fr | Q4: Sa | R4: So | S4: Mo | T4: Di | U4: Mi | V4: Do | W4: Fr | X4: Sa | Y4: So | Z4: Mo | AA4: Di | AB4: Mi | AC4: Do | AD4: Fr | AE4: Sa | AF4: So
A5: KW | B5: 53 | E5: 1 | L5: 2 | S5: 3 | Z5: 4
A6: Breig | B6: =IF(Dienstplan!B7="","",Dienstplan!B7) | C6: =IF(Dienstplan!C7="","",Dienstplan!C7) | D6: =IF(Dienstplan!D7="","",Dienstplan!D7) | E6: =IF(Dienstplan!E7="","",Dienstplan!E7) | F6: =IF(Dienstplan!F7="","",Dienstplan!F7) | G6: =IF(Dienstplan!G7="","",Dienstplan!G7) | H6: =IF(Dienstplan!H7="","",Dienstplan!H7) | I6: =IF(Dienstplan!I7="","",Dienstplan!I7) | ... AF6: =IF(Dienstplan!AF7="","",Dienstplan!AF7)
A7: Siebert | B7: =IF(Dienstplan!B8="","",Dienstplan!B8) | C7: =IF(Dienstplan!C8="","",Dienstplan!C8) | D7: =IF(Dienstplan!D8="","",Dienstplan!D8) | E7: =IF(Dienstplan!E8="","",Dienstplan!E8) | F7: =IF(Dienstplan!F8="","",Dienstplan!F8) | G7: =IF(Dienstplan!G8="","",Dienstplan!G8) | H7: =IF(Dienstplan!H8="","",Dienstplan!H8) | I7: =IF(Dienstplan!I8="","",Dienstplan!I8) | ... AF7: =IF(Dienstplan!AF8="","",Dienstplan!AF8)
A8: Jochim | B8: =IF(Dienstplan!B9="","",Dienstplan!B9) | C8: =IF(Dienstplan!C9="","",Dienstplan!C9) | D8: =IF(Dienstplan!D9="","",Dienstplan!D9) | E8: =IF(Dienstplan!E9="","",Dienstplan!E9) | F8: =IF(Dienstplan!F9="","",Dienstplan!F9) | G8: =IF(Dienstplan!G9="","",Dienstplan!G9) | H8: =IF(Dienstplan!H9="","",Dienstplan!H9) | I8: =IF(Dienstplan!I9="","",Dienstplan!I9) | ... AF8: =IF(Dienstplan!AF9="","",Dienstplan!AF9)
A9: Wunsch | B9: =IF(Dienstplan!B10="","",Dienstplan!B10) | C9: =IF(Dienstplan!C10="","",Dienstplan!C10) | D9: =IF(Dienstplan!D10="","",Dienstplan!D10) | E9: =IF(Dienstplan!E10="","",Dienstplan!E10) | F9: =IF(Dienstplan!F10="","",Dienstplan!F10) | G9: =IF(Dienstplan!G10="","",Dienstplan!G10) | H9: =IF(Dienstplan!H10="","",Dienstplan!H10) | I9: =IF(Dienstplan!I10="","",Dienstplan!I10) | ... AF9: =IF(Dienstplan!AF10="","",Dienstplan!AF10)
A10: Göpfrich | B10: =IF(Dienstplan!B11="","",Dienstplan!B11) | C10: =IF(Dienstplan!C11="","",Dienstplan!C11) | D10: =IF(Dienstplan!D11="","",Dienstplan!D11) | E10: =IF(Dienstplan!E11="","",Dienstplan!E11) | F10: =IF(Dienstplan!F11="","",Dienstplan!F11) | G10: =IF(Dienstplan!G11="","",Dienstplan!G11) | H10: =IF(Dienstplan!H11="","",Dienstplan!H11) | I10: =IF(Dienstplan!I11="","",Dienstplan!I11) | ... AF10: =IF(Dienstplan!AF11="","",Dienstplan!AF11)
A11: Zeller | B11: =IF(Dienstplan!B12="","",Dienstplan!B12) | C11: =IF(Dienstplan!C12="","",Dienstplan!C12) | D11: =IF(Dienstplan!D12="","",Dienstplan!D12) | E11: =IF(Dienstplan!E12="","",Dienstplan!E12) | F11: =IF(Dienstplan!F12="","",Dienstplan!F12) | G11: =IF(Dienstplan!G12="","",Dienstplan!G12) | H11: =IF(Dienstplan!H12="","",Dienstplan!H12) | I11: =IF(Dienstplan!I12="","",Dienstplan!I12) | ... AF11: =IF(Dienstplan!AF12="","",Dienstplan!AF12)
A12: Behrendt | B12: =IF(Dienstplan!B13="","",Dienstplan!B13) | C12: =IF(Dienstplan!C13="","",Dienstplan!C13) | D12: =IF(Dienstplan!D13="","",Dienstplan!D13) | E12: =IF(Dienstplan!E13="","",Dienstplan!E13) | F12: =IF(Dienstplan!F13="","",Dienstplan!F13) | G12: =IF(Dienstplan!G13="","",Dienstplan!G13) | H12: =IF(Dienstplan!H13="","",Dienstplan!H13) | I12: =IF(Dienstplan!I13="","",Dienstplan!I13) | ... AF12: =IF(Dienstplan!AF13="","",Dienstplan!AF13)
A13: Krempl | B13: =IF(Dienstplan!B14="","",Dienstplan!B14) | C13: =IF(Dienstplan!C14="","",Dienstplan!C14) | D13: =IF(Dienstplan!D14="","",Dienstplan!D14) | E13: =IF(Dienstplan!E14="","",Dienstplan!E14) | F13: =IF(Dienstplan!F14="","",Dienstplan!F14) | G13: =IF(Dienstplan!G14="","",Dienstplan!G14) | H13: =IF(Dienstplan!H14="","",Dienstplan!H14) | I13: =IF(Dienstplan!I14="","",Dienstplan!I14) | ... AF13: =IF(Dienstplan!AF14="","",Dienstplan!AF14)
A14: Putschler | B14: =IF(Dienstplan!B15="","",Dienstplan!B15) | C14: =IF(Dienstplan!C15="","",Dienstplan!C15) | D14: =IF(Dienstplan!D15="","",Dienstplan!D15) | E14: =IF(Dienstplan!E15="","",Dienstplan!E15) | F14: =IF(Dienstplan!F15="","",Dienstplan!F15) | G14: =IF(Dienstplan!G15="","",Dienstplan!G15) | H14: =IF(Dienstplan!H15="","",Dienstplan!H15) | I14: =IF(Dienstplan!I15="","",Dienstplan!I15) | ... AF14: =IF(Dienstplan!AF15="","",Dienstplan!AF15)
A15: Kunz | B15: =IF(Dienstplan!B16="","",Dienstplan!B16) | C15: =IF(Dienstplan!C16="","",Dienstplan!C16) | D15: =IF(Dienstplan!D16="","",Dienstplan!D16) | E15: =IF(Dienstplan!E16="","",Dienstplan!E16) | F15: =IF(Dienstplan!F16="","",Dienstplan!F16) | G15: =IF(Dienstplan!G16="","",Dienstplan!G16) | H15: =IF(Dienstplan!H16="","",Dienstplan!H16) | I15: =IF(Dienstplan!I16="","",Dienstplan!I16) | ... AF15: =IF(Dienstplan!AF16="","",Dienstplan!AF16)
A16: Schmidt | B16: =IF(Dienstplan!B17="","",Dienstplan!B17) | C16: =IF(Dienstplan!C17="","",Dienstplan!C17) | D16: =IF(Dienstplan!D17="","",Dienstplan!D17) | E16: =IF(Dienstplan!E17="","",Dienstplan!E17) | F16: =IF(Dienstplan!F17="","",Dienstplan!F17) | G16: =IF(Dienstplan!G17="","",Dienstplan!G17) | H16: =IF(Dienstplan!H17="","",Dienstplan!H17) | I16: =IF(Dienstplan!I17="","",Dienstplan!I17) | ... AF16: =IF(Dienstplan!AF17="","",Dienstplan!AF17)
A17: Radimersky | B17: =IF(Dienstplan!B18="","",Dienstplan!B18) | C17: =IF(Dienstplan!C18="","",Dienstplan!C18) | D17: =IF(Dienstplan!D18="","",Dienstplan!D18) | E17: =IF(Dienstplan!E18="","",Dienstplan!E18) | F17: =IF(Dienstplan!F18="","",Dienstplan!F18) | G17: =IF(Dienstplan!G18="","",Dienstplan!G18) | H17: =IF(Dienstplan!H18="","",Dienstplan!H18) | I17: =IF(Dienstplan!I18="","",Dienstplan!I18) | ... AF17: =IF(Dienstplan!AF18="","",Dienstplan!AF18)
A18: Besetzung | E18: =IF(AND(COUNTIF(E6:E17,"FI")>0,COUNTIF(E6:E17,"SI")>0,COUNTIF(E6:E17,"NI")>0),"","!") | F18: =IF(AND(COUNTIF(F6:F17,"FI")>0,COUNTIF(F6:F17,"SI")>0,COUNTIF(F6:F17,"NI")>0),"","!") | H18: =IF(AND(COUNTIF(H6:H17,"FI")>0,COUNTIF(H6:H17,"SI")>0,COUNTIF(H6:H17,"NI")>0),"","!") | I18: =IF(AND(COUNTIF(I6:I17,"FI")>0,COUNTIF(I6:I17,"SI")>0),"","!") | L18: =IF(AND(COUNTIF(L6:L17,"FI")>0,COUNTIF(L6:L17,"SI")>0,COUNTIF(L6:L17,"NI")>0),"","!") | M18: =IF(AND(COUNTIF(M6:M17,"FI")>0,COUNTIF(M6:M17,"SI")>0,COUNTIF(M6:M17,"NI")>0),"","!") | N18: =IF(AND(COUNTIF(N6:N17,"FI")>0,COUNTIF(N6:N17,"SI")>0,COUNTIF(N6:N17,"NI")>0),"","!") | O18: =IF(AND(COUNTIF(O6:O17,"FI")>0,COUNTIF(O6:O17,"SI")>0,COUNTIF(O6:O17,"NI")>0),"","!") | P18: =IF(AND(COUNTIF(P6:P17,"FI")>0,COUNTIF(P6:P17,"SI")>0),"","!") | S18: =IF(AND(COUNTIF(S6:S17,"FI")>0,COUNTIF(S6:S17,"SI")>0,COUNTIF(S6:S17,"NI")>0),"","!") | T18: =IF(AND(COUNTIF(T6:T17,"FI")>0,COUNTIF(T6:T17,"SI")>0,COUNTIF(T6:T17,"NI")>0),"","!") | U18: =IF(AND(COUNTIF(U6:U17,"FI")>0,COUNTIF(U6:U17,"SI")>0,COUNTIF(U6:U17,"NI")>0),"","!") | V18: =IF(AND(COUNTIF(V6:V17,"FI")>0,COUNTIF(V6:V17,"SI")>0,COUNTIF(V6:V17,"NI")>0),"","!") | W18: =IF(AND(COUNTIF(W6:W17,"FI")>0,COUNTIF(W6:W17,"SI")>0),"","!") | Z18: =IF(AND(COUNTIF(Z6:Z17,"FI")>0,COUNTIF(Z6:Z17,"SI")>0,COUNTIF(Z6:Z17,"NI")>0),"","!") | AA18: =IF(AND(COUNTIF(AA6:AA17,"FI")>0,COUNTIF(AA6:AA17,"SI")>0,COUNTIF(AA6:AA17,"NI")>0),"","!") | AB18: =IF(AND(COUNTIF(AB6:AB17,"FI")>0,COUNTIF(AB6:AB17,"SI")>0,COUNTIF(AB6:AB17,"NI")>0),"","!") | AC18: =IF(AND(COUNTIF(AC6:AC17,"FI")>0,COUNTIF(AC6:AC17,"SI")>0,COUNTIF(AC6:AC17,"NI")>0),"","!") | AD18: =IF(AND(COUNTIF(AD6:AD17,"FI")>0,COUNTIF(AD6:AD17,"SI")>0),"","!")
A20: Legende | P20: Unterschriften
A21: U | D21: Urlaub | H21: FII 06:00-14:00 | K21: Frühschicht II | P21: Erstellt von:
A22: EH 08:00-17:00 | D22: Erste Hilfe | H22: SI 14:00-22:00 | K22: Spätschicht I
A23: KU 08:30-16:30 | D23: Kuppenheim | H23: SII 14:00-21:00 | K23: Spätschicht II | P23: Datum / Unterschrift
A24: A | D24: AU | H24: NI 22:00-06:00 | K24: Nachtschicht I
A25: GT | D25: Gleittag | H25: DI 08:00-15:30 | K25: Dienst I | P25: Genehmigt von:
A26: NST | D26: Ausgleichstag | H26: DII 08:30-16:00 | K26: Dienst II
A27: Fobi | D27: Fortbildung | H27: KT IRTAZ | K27: Koordination | P27: Datum / Unterschrift
A28: FI 06:00-14:00 | D28: Frühschicht I | H28: SD Individuell | K28: Sonderdienst
D29: Wochenende / Feiertag

Sheet Februar
A1: Dienstplan Februar 2027 | Z1: AT: 20 Sa: 4
P2: Faschingsferien
A3: Tag | B3: 1 | C3: 2 | D3: 3 | E3: 4 | F3: 5 | G3: 6 | H3: 7 | I3: 8 | J3: 9 | K3: 10 | L3: 11 | M3: 12 | N3: 13 | O3: 14 | P3: 15 | Q3: 16 | R3: 17 | S3: 18 | T3: 19 | U3: 20 | V3: 21 | W3: 22 | X3: 23 | Y3: 24 | Z3: 25 | AA3: 26 | AB3: 27 | AC3: 28
A4: WT | B4: Mo | C4: Di | D4: Mi | E4: Do | F4: Fr | G4: Sa | H4: So | I4: Mo | J4: Di | K4: Mi | L4: Do | M4: Fr | N4: Sa | O4: So | P4: Mo | Q4: Di | R4: Mi | S4: Do | T4: Fr | U4: Sa | V4: So | W4: Mo | X4: Di | Y4: Mi | Z4: Do | AA4: Fr | AB4: Sa | AC4: So
A5: KW | B5: 5 | I5: 6 | P5: 7 | W5: 8
A6: Breig | B6: =IF(Dienstplan!B26="","",Dienstplan!B26) | C6: =IF(Dienstplan!C26="","",Dienstplan!C26) | D6: =IF(Dienstplan!D26="","",Dienstplan!D26) | E6: =IF(Dienstplan!E26="","",Dienstplan!E26) | F6: =IF(Dienstplan!F26="","",Dienstplan!F26) | G6: =IF(Dienstplan!G26="","",Dienstplan!G26) | H6: =IF(Dienstplan!H26="","",Dienstplan!H26) | I6: =IF(Dienstplan!I26="","",Dienstplan!I26) | ... AC6: =IF(Dienstplan!AC26="","",Dienstplan!AC26)
A7: Siebert | B7: =IF(Dienstplan!B27="","",Dienstplan!B27) | C7: =IF(Dienstplan!C27="","",Dienstplan!C27) | D7: =IF(Dienstplan!D27="","",Dienstplan!D27) | E7: =IF(Dienstplan!E27="","",Dienstplan!E27) | F7: =IF(Dienstplan!F27="","",Dienstplan!F27) | G7: =IF(Dienstplan!G27="","",Dienstplan!G27) | H7: =IF(Dienstplan!H27="","",Dienstplan!H27) | I7: =IF(Dienstplan!I27="","",Dienstplan!I27) | ... AC7: =IF(Dienstplan!AC27="","",Dienstplan!AC27)
A8: Jochim | B8: =IF(Dienstplan!B28="","",Dienstplan!B28) | C8: =IF(Dienstplan!C28="","",Dienstplan!C28) | D8: =IF(Dienstplan!D28="","",Dienstplan!D28) | E8: =IF(Dienstplan!E28="","",Dienstplan!E28) | F8: =IF(Dienstplan!F28="","",Dienstplan!F28) | G8: =IF(Dienstplan!G28="","",Dienstplan!G28) | H8: =IF(Dienstplan!H28="","",Dienstplan!H28) | I8: =IF(Dienstplan!I28="","",Dienstplan!I28) | ... AC8: =IF(Dienstplan!AC28="","",Dienstplan!AC28)
A9: Wunsch | B9: =IF(Dienstplan!B29="","",Dienstplan!B29) | C9: =IF(Dienstplan!C29="","",Dienstplan!C29) | D9: =IF(Dienstplan!D29="","",Dienstplan!D29) | E9: =IF(Dienstplan!E29="","",Dienstplan!E29) | F9: =IF(Dienstplan!F29="","",Dienstplan!F29) | G9: =IF(Dienstplan!G29="","",Dienstplan!G29) | H9: =IF(Dienstplan!H29="","",Dienstplan!H29) | I9: =IF(Dienstplan!I29="","",Dienstplan!I29) | ... AC9: =IF(Dienstplan!AC29="","",Dienstplan!AC29)
A10: Göpfrich | B10: =IF(Dienstplan!B30="","",Dienstplan!B30) | C10: =IF(Dienstplan!C30="","",Dienstplan!C30) | D10: =IF(Dienstplan!D30="","",Dienstplan!D30) | E10: =IF(Dienstplan!E30="","",Dienstplan!E30) | F10: =IF(Dienstplan!F30="","",Dienstplan!F30) | G10: =IF(Dienstplan!G30="","",Dienstplan!G30) | H10: =IF(Dienstplan!H30="","",Dienstplan!H30) | I10: =IF(Dienstplan!I30="","",Dienstplan!I30) | ... AC10: =IF(Dienstplan!AC30="","",Dienstplan!AC30)
A11: Zeller | B11: =IF(Dienstplan!B31="","",Dienstplan!B31) | C11: =IF(Dienstplan!C31="","",Dienstplan!C31) | D11: =IF(Dienstplan!D31="","",Dienstplan!D31) | E11: =IF(Dienstplan!E31="","",Dienstplan!E31) | F11: =IF(Dienstplan!F31="","",Dienstplan!F31) | G11: =IF(Dienstplan!G31="","",Dienstplan!G31) | H11: =IF(Dienstplan!H31="","",Dienstplan!H31) | I11: =IF(Dienstplan!I31="","",Dienstplan!I31) | ... AC11: =IF(Dienstplan!AC31="","",Dienstplan!AC31)
A12: Behrendt | B12: =IF(Dienstplan!B32="","",Dienstplan!B32) | C12: =IF(Dienstplan!C32="","",Dienstplan!C32) | D12: =IF(Dienstplan!D32="","",Dienstplan!D32) | E12: =IF(Dienstplan!E32="","",Dienstplan!E32) | F12: =IF(Dienstplan!F32="","",Dienstplan!F32) | G12: =IF(Dienstplan!G32="","",Dienstplan!G32) | H12: =IF(Dienstplan!H32="","",Dienstplan!H32) | I12: =IF(Dienstplan!I32="","",Dienstplan!I32) | ... AC12: =IF(Dienstplan!AC32="","",Dienstplan!AC32)
A13: Krempl | B13: =IF(Dienstplan!B33="","",Dienstplan!B33) | C13: =IF(Dienstplan!C33="","",Dienstplan!C33) | D13: =IF(Dienstplan!D33="","",Dienstplan!D33) | E13: =IF(Dienstplan!E33="","",Dienstplan!E33) | F13: =IF(Dienstplan!F33="","",Dienstplan!F33) | G13: =IF(Dienstplan!G33="","",Dienstplan!G33) | H13: =IF(Dienstplan!H33="","",Dienstplan!H33) | I13: =IF(Dienstplan!I33="","",Dienstplan!I33) | ... AC13: =IF(Dienstplan!AC33="","",Dienstplan!AC33)
A14: Putschler | B14: =IF(Dienstplan!B34="","",Dienstplan!B34) | C14: =IF(Dienstplan!C34="","",Dienstplan!C34) | D14: =IF(Dienstplan!D34="","",Dienstplan!D34) | E14: =IF(Dienstplan!E34="","",Dienstplan!E34) | F14: =IF(Dienstplan!F34="","",Dienstplan!F34) | G14: =IF(Dienstplan!G34="","",Dienstplan!G34) | H14: =IF(Dienstplan!H34="","",Dienstplan!H34) | I14: =IF(Dienstplan!I34="","",Dienstplan!I34) | ... AC14: =IF(Dienstplan!AC34="","",Dienstplan!AC34)
A15: Kunz | B15: =IF(Dienstplan!B35="","",Dienstplan!B35) | C15: =IF(Dienstplan!C35="","",Dienstplan!C35) | D15: =IF(Dienstplan!D35="","",Dienstplan!D35) | E15: =IF(Dienstplan!E35="","",Dienstplan!E35) | F15: =IF(Dienstplan!F35="","",Dienstplan!F35) | G15: =IF(Dienstplan!G35="","",Dienstplan!G35) | H15: =IF(Dienstplan!H35="","",Dienstplan!H35) | I15: =IF(Dienstplan!I35="","",Dienstplan!I35) | ... AC15: =IF(Dienstplan!AC35="","",Dienstplan!AC35)
A16: Schmidt | B16: =IF(Dienstplan!B36="","",Dienstplan!B36) | C16: =IF(Dienstplan!C36="","",Dienstplan!C36) | D16: =IF(Dienstplan!D36="","",Dienstplan!D36) | E16: =IF(Dienstplan!E36="","",Dienstplan!E36) | F16: =IF(Dienstplan!F36="","",Dienstplan!F36) | G16: =IF(Dienstplan!G36="","",Dienstplan!G36) | H16: =IF(Dienstplan!H36="","",Dienstplan!H36) | I16: =IF(Dienstplan!I36="","",Dienstplan!I36) | ... AC16: =IF(Dienstplan!AC36="","",Dienstplan!AC36)
A17: Radimersky | B17: =IF(Dienstplan!B37="","",Dienstplan!B37) | C17: =IF(Dienstplan!C37="","",Dienstplan!C37) | D17: =IF(Dienstplan!D37="","",Dienstplan!D37) | E17: =IF(Dienstplan!E37="","",Dienstplan!E37) | F17: =IF(Dienstplan!F37="","",Dienstplan!F37) | G17: =IF(Dienstplan!G37="","",Dienstplan!G37) | H17: =IF(Dienstplan!H37="","",Dienstplan!H37) | I17: =IF(Dienstplan!I37="","",Dienstplan!I37) | ... AC17: =IF(Dienstplan!AC37="","",Dienstplan!AC37)
A18: Besetzung | B18: =IF(AND(COUNTIF(B6:B17,"FI")>0,COUNTIF(B6:B17,"SI")>0,COUNTIF(B6:B17,"NI")>0),"","!") | C18: =IF(AND(COUNTIF(C6:C17,"FI")>0,COUNTIF(C6:C17,"SI")>0,COUNTIF(C6:C17,"NI")>0),"","!") | D18: =IF(AND(COUNTIF(D6:D17,"FI")>0,COUNTIF(D6:D17,"SI")>0,COUNTIF(D6:D17,"NI")>0),"","!") | E18: =IF(AND(COUNTIF(E6:E17,"FI")>0,COUNTIF(E6:E17,"SI")>0,COUNTIF(E6:E17,"NI")>0),"","!") | F18: =IF(AND(COUNTIF(F6:F17,"FI")>0,COUNTIF(F6:F17,"SI")>0),"","!") | I18: =IF(AND(COUNTIF(I6:I17,"FI")>0,COUNTIF(I6:I17,"SI")>0,COUNTIF(I6:I17,"NI")>0),"","!") | J18: =IF(AND(COUNTIF(J6:J17,"FI")>0,COUNTIF(J6:J17,"SI")>0,COUNTIF(J6:J17,"NI")>0),"","!") | K18: =IF(AND(COUNTIF(K6:K17,"FI")>0,COUNTIF(K6:K17,"SI")>0,COUNTIF(K6:K17,"NI")>0),"","!") | L18: =IF(AND(COUNTIF(L6:L17,"FI")>0,COUNTIF(L6:L17,"SI")>0,COUNTIF(L6:L17,"NI")>0),"","!") | M18: =IF(AND(COUNTIF(M6:M17,"FI")>0,COUNTIF(M6:M17,"SI")>0),"","!") | P18: =IF(AND(COUNTIF(P6:P17,"FI")>0,COUNTIF(P6:P17,"SI")>0,COUNTIF(P6:P17,"NI")>0),"","!") | Q18: =IF(AND(COUNTIF(Q6:Q17,"FI")>0,COUNTIF(Q6:Q17,"SI")>0,COUNTIF(Q6:Q17,"NI")>0),"","!") | R18: =IF(AND(COUNTIF(R6:R17,"FI")>0,COUNTIF(R6:R17,"SI")>0,COUNTIF(R6:R17,"NI")>0),"","!") | S18: =IF(AND(COUNTIF(S6:S17,"FI")>0,COUNTIF(S6:S17,"SI")>0,COUNTIF(S6:S17,"NI")>0),"","!") | T18: =IF(AND(COUNTIF(T6:T17,"FI")>0,COUNTIF(T6:T17,"SI")>0),"","!") | W18: =IF(AND(COUNTIF(W6:W17,"FI")>0,COUNTIF(W6:W17,"SI")>0,COUNTIF(W6:W17,"NI")>0),"","!") | X18: =IF(AND(COUNTIF(X6:X17,"FI")>0,COUNTIF(X6:X17,"SI")>0,COUNTIF(X6:X17,"NI")>0),"","!") | Y18: =IF(AND(COUNTIF(Y6:Y17,"FI")>0,COUNTIF(Y6:Y17,"SI")>0,COUNTIF(Y6:Y17,"NI")>0),"","!") | Z18: =IF(AND(COUNTIF(Z6:Z17,"FI")>0,COUNTIF(Z6:Z17,"SI")>0,COUNTIF(Z6:Z17,"NI")>0),"","!") | AA18: =IF(AND(COUNTIF(AA6:AA17,"FI")>0,COUNTIF(AA6:AA17,"SI")>0),"","!")
A20: Legende | P20: Unterschriften
A21: U | D21: Urlaub | H21: FII 06:00-14:00 | K21: Frühschicht II | P21: Erstellt von:
A22: EH 08:00-17:00 | D22: Erste Hilfe | H22: SI 14:00-22:00 | K22: Spätschicht I
A23: KU 08:30-16:30 | D23: Kuppenheim | H23: SII 14:00-21:00 | K23: Spätschicht II | P23: Datum / Unterschrift
A24: A | D24: AU | H24: NI 22:00-06:00 | K24: Nachtschicht I
A25: GT | D25: Gleittag | H25: DI 08:00-15:30 | K25: Dienst I | P25: Genehmigt von:
A26: NST | D26: Ausgleichstag | H26: DII 08:30-16:00 | K26: Dienst II
A27: Fobi | D27: Fortbildung | H27: KT IRTAZ | K27: Koordination | P27: Datum / Unterschrift
A28: FI 06:00-14:00 | D28: Frühschicht I | H28: SD Individuell | K28: Sonderdienst
D29: Wochenende / Feiertag

Sheet März
A1: Dienstplan März 2027 | AC1: AT: 21 Sa: 4
AB2: Osterferien
A3: Tag | B3: 1 | C3: 2 | D3: 3 | E3: 4 | F3: 5 | G3: 6 | H3: 7 | I3: 8 | J3: 9 | K3: 10 | L3: 11 | M3: 12 | N3: 13 | O3: 14 | P3: 15 | Q3: 16 | R3: 17 | S3: 18 | T3: 19 | U3: 20 | V3: 21 | W3: 22 | X3: 23 | Y3: 24 | Z3: 25 | AA3: 26 | AB3: 27 | AC3: 28 | AD3: 29 | AE3: 30 | AF3: 31
A4: WT | B4: Mo | C4: Di | D4: Mi | E4: Do | F4: Fr | G4: Sa | H4: So | I4: Mo | J4: Di | K4: Mi | L4: Do | M4: Fr | N4: Sa | O4: So | P4: Mo | Q4: Di | R4: Mi | S4: Do | T4: Fr | U4: Sa | V4: So | W4: Mo | X4: Di | Y4: Mi | Z4: Do | AA4: Fr | AB4: Sa | AC4: So | AD4: Mo | AE4: Di | AF4: Mi
A5: KW | B5: 9 | I5: 10 | P5: 11 | W5: 12 | AD5: 13
A6: Breig | B6: =IF(Dienstplan!B45="","",Dienstplan!B45) | C6: =IF(Dienstplan!C45="","",Dienstplan!C45) | D6: =IF(Dienstplan!D45="","",Dienstplan!D45) | E6: =IF(Dienstplan!E45="","",Dienstplan!E45) | F6: =IF(Dienstplan!F45="","",Dienstplan!F45) | G6: =IF(Dienstplan!G45="","",Dienstplan!G45) | H6: =IF(Dienstplan!H45="","",Dienstplan!H45) | I6: =IF(Dienstplan!I45="","",Dienstplan!I45) | ... AF6: =IF(Dienstplan!AF45="","",Dienstplan!AF45)
A7: Siebert | B7: =IF(Dienstplan!B46="","",Dienstplan!B46) | C7: =IF(Dienstplan!C46="","",Dienstplan!C46) | D7: =IF(Dienstplan!D46="","",Dienstplan!D46) | E7: =IF(Dienstplan!E46="","",Dienstplan!E46) | F7: =IF(Dienstplan!F46="","",Dienstplan!F46) | G7: =IF(Dienstplan!G46="","",Dienstplan!G46) | H7: =IF(Dienstplan!H46="","",Dienstplan!H46) | I7: =IF(Dienstplan!I46="","",Dienstplan!I46) | ... AF7: =IF(Dienstplan!AF46="","",Dienstplan!AF46)
A8: Jochim | B8: =IF(Dienstplan!B47="","",Dienstplan!B47) | C8: =IF(Dienstplan!C47="","",Dienstplan!C47) | D8: =IF(Dienstplan!D47="","",Dienstplan!D47) | E8: =IF(Dienstplan!E47="","",Dienstplan!E47) | F8: =IF(Dienstplan!F47="","",Dienstplan!F47) | G8: =IF(Dienstplan!G47="","",Dienstplan!G47) | H8: =IF(Dienstplan!H47="","",Dienstplan!H47) | I8: =IF(Dienstplan!I47="","",Dienstplan!I47) | ... AF8: =IF(Dienstplan!AF47="","",Dienstplan!AF47)
A9: Wunsch | B9: =IF(Dienstplan!B48="","",Dienstplan!B48) | C9: =IF(Dienstplan!C48="","",Dienstplan!C48) | D9: =IF(Dienstplan!D48="","",Dienstplan!D48) | E9: =IF(Dienstplan!E48="","",Dienstplan!E48) | F9: =IF(Dienstplan!F48="","",Dienstplan!F48) | G9: =IF(Dienstplan!G48="","",Dienstplan!G48) | H9: =IF(Dienstplan!H48="","",Dienstplan!H48) | I9: =IF(Dienstplan!I48="","",Dienstplan!I48) | ... AF9: =IF(Dienstplan!AF48="","",Dienstplan!AF48)
A10: Göpfrich | B10: =IF(Dienstplan!B49="","",Dienstplan!B49) | C10: =IF(Dienstplan!C49="","",Dienstplan!C49) | D10: =IF(Dienstplan!D49="","",Dienstplan!D49) | E10: =IF(Dienstplan!E49="","",Dienstplan!E49) | F10: =IF(Dienstplan!F49="","",Dienstplan!F49) | G10: =IF(Dienstplan!G49="","",Dienstplan!G49) | H10: =IF(Dienstplan!H49="","",Dienstplan!H49) | I10: =IF(Dienstplan!I49="","",Dienstplan!I49) | ... AF10: =IF(Dienstplan!AF49="","",Dienstplan!AF49)
A11: Zeller | B11: =IF(Dienstplan!B50="","",Dienstplan!B50) | C11: =IF(Dienstplan!C50="","",Dienstplan!C50) | D11: =IF(Dienstplan!D50="","",Dienstplan!D50) | E11: =IF(Dienstplan!E50="","",Dienstplan!E50) | F11: =IF(Dienstplan!F50="","",Dienstplan!F50) | G11: =IF(Dienstplan!G50="","",Dienstplan!G50) | H11: =IF(Dienstplan!H50="","",Dienstplan!H50) | I11: =IF(Dienstplan!I50="","",Dienstplan!I50) | ... AF11: =IF(Dienstplan!AF50="","",Dienstplan!AF50)
A12: Behrendt | B12: =IF(Dienstplan!B51="","",Dienstplan!B51) | C12: =IF(Dienstplan!C51="","",Dienstplan!C51) | D12: =IF(Dienstplan!D51="","",Dienstplan!D51) | E12: =IF(Dienstplan!E51="","",Dienstplan!E51) | F12: =IF(Dienstplan!F51="","",Dienstplan!F51) | G12: =IF(Dienstplan!G51="","",Dienstplan!G51) | H12: =IF(Dienstplan!H51="","",Dienstplan!H51) | I12: =IF(Dienstplan!I51="","",Dienstplan!I51) | ... AF12: =IF(Dienstplan!AF51="","",Dienstplan!AF51)
A13: Krempl | B13: =IF(Dienstplan!B52="","",Dienstplan!B52) | C13: =IF(Dienstplan!C52="","",Dienstplan!C52) | D13: =IF(Dienstplan!D52="","",Dienstplan!D52) | E13: =IF(Dienstplan!E52="","",Dienstplan!E52) | F13: =IF(Dienstplan!F52="","",Dienstplan!F52) | G13: =IF(Dienstplan!G52="","",Dienstplan!G52) | H13: =IF(Dienstplan!H52="","",Dienstplan!H52) | I13: =IF(Dienstplan!I52="","",Dienstplan!I52) | ... AF13: =IF(Dienstplan!AF52="","",Dienstplan!AF52)
A14: Putschler | B14: =IF(Dienstplan!B53="","",Dienstplan!B53) | C14: =IF(Dienstplan!C53="","",Dienstplan!C53) | D14: =IF(Dienstplan!D53="","",Dienstplan!D53) | E14: =IF(Dienstplan!E53="","",Dienstplan!E53) | F14: =IF(Dienstplan!F53="","",Dienstplan!F53) | G14: =IF(Dienstplan!G53="","",Dienstplan!G53) | H14: =IF(Dienstplan!H53="","",Dienstplan!H53) | I14: =IF(Dienstplan!I53="","",Dienstplan!I53) | ... AF14: =IF(Dienstplan!AF53="","",Dienstplan!AF53)
A15: Kunz | B15: =IF(Dienstplan!B54="","",Dienstplan!B54) | C15: =IF(Dienstplan!C54="","",Dienstplan!C54) | D15: =IF(Dienstplan!D54="","",Dienstplan!D54) | E15: =IF(Dienstplan!E54="","",Dienstplan!E54) | F15: =IF(Dienstplan!F54="","",Dienstplan!F54) | G15: =IF(Dienstplan!G54="","",Dienstplan!G54) | H15: =IF(Dienstplan!H54="","",Dienstplan!H54) | I15: =IF(Dienstplan!I54="","",Dienstplan!I54) | ... AF15: =IF(Dienstplan!AF54="","",Dienstplan!AF54)
A16: Schmidt | B16: =IF(Dienstplan!B55="","",Dienstplan!B55) | C16: =IF(Dienstplan!C55="","",Dienstplan!C55) | D16: =IF(Dienstplan!D55="","",Dienstplan!D55) | E16: =IF(Dienstplan!E55="","",Dienstplan!E55) | F16: =IF(Dienstplan!F55="","",Dienstplan!F55) | G16: =IF(Dienstplan!G55="","",Dienstplan!G55) | H16: =IF(Dienstplan!H55="","",Dienstplan!H55) | I16: =IF(Dienstplan!I55="","",Dienstplan!I55) | ... AF16: =IF(Dienstplan!AF55="","",Dienstplan!AF55)
A17: Radimersky | B17: =IF(Dienstplan!B56="","",Dienstplan!B56) | C17: =IF(Dienstplan!C56="","",Dienstplan!C56) | D17: =IF(Dienstplan!D56="","",Dienstplan!D56) | E17: =IF(Dienstplan!E56="","",Dienstplan!E56) | F17: =IF(Dienstplan!F56="","",Dienstplan!F56) | G17: =IF(Dienstplan!G56="","",Dienstplan!G56) | H17: =IF(Dienstplan!H56="","",Dienstplan!H56) | I17: =IF(Dienstplan!I56="","",Dienstplan!I56) | ... AF17: =IF(Dienstplan!AF56="","",Dienstplan!AF56)
A18: Besetzung | B18: =IF(AND(COUNTIF(B6:B17,"FI")>0,COUNTIF(B6:B17,"SI")>0,COUNTIF(B6:B17,"NI")>0),"","!") | C18: =IF(AND(COUNTIF(C6:C17,"FI")>0,COUNTIF(C6:C17,"SI")>0,COUNTIF(C6:C17,"NI")>0),"","!") | D18: =IF(AND(COUNTIF(D6:D17,"FI")>0,COUNTIF(D6:D17,"SI")>0,COUNTIF(D6:D17,"NI")>0),"","!") | E18: =IF(AND(COUNTIF(E6:E17,"FI")>0,COUNTIF(E6:E17,"SI")>0,COUNTIF(E6:E17,"NI")>0),"","!") | F18: =IF(AND(COUNTIF(F6:F17,"FI")>0,COUNTIF(F6:F17,"SI")>0),"","!") | I18: =IF(AND(COUNTIF(I6:I17,"FI")>0,COUNTIF(I6:I17,"SI")>0,COUNTIF(I6:I17,"NI")>0),"","!") | J18: =IF(AND(COUNTIF(J6:J17,"FI")>0,COUNTIF(J6:J17,"SI")>0,COUNTIF(J6:J17,"NI")>0),"","!") | K18: =IF(AND(COUNTIF(K6:K17,"FI")>0,COUNTIF(K6:K17,"SI")>0,COUNTIF(K6:K17,"NI")>0),"","!") | L18: =IF(AND(COUNTIF(L6:L17,"FI")>0,COUNTIF(L6:L17,"SI")>0,COUNTIF(L6:L17,"NI")>0),"","!") | M18: =IF(AND(COUNTIF(M6:M17,"FI")>0,COUNTIF(M6:M17,"SI")>0),"","!") | P18: =IF(AND(COUNTIF(P6:P17,"FI")>0,COUNTIF(P6:P17,"SI")>0,COUNTIF(P6:P17,"NI")>0),"","!") | Q18: =IF(AND(COUNTIF(Q6:Q17,"FI")>0,COUNTIF(Q6:Q17,"SI")>0,COUNTIF(Q6:Q17,"NI")>0),"","!") | R18: =IF(AND(COUNTIF(R6:R17,"FI")>0,COUNTIF(R6:R17,"SI")>0,COUNTIF(R6:R17,"NI")>0),"","!") | S18: =IF(AND(COUNTIF(S6:S17,"FI")>0,COUNTIF(S6:S17,"SI")>0,COUNTIF(S6:S17,"NI")>0),"","!") | T18: =IF(AND(COUNTIF(T6:T17,"FI")>0,COUNTIF(T6:T17,"SI")>0),"","!") | W18: =IF(AND(COUNTIF(W6:W17,"FI")>0,COUNTIF(W6:W17,"SI")>0,COUNTIF(W6:W17,"NI")>0),"","!") | X18: =IF(AND(COUNTIF(X6:X17,"FI")>0,COUNTIF(X6:X17,"SI")>0,COUNTIF(X6:X17,"NI")>0),"","!") | Y18: =IF(AND(COUNTIF(Y6:Y17,"FI")>0,COUNTIF(Y6:Y17,"SI")>0,COUNTIF(Y6:Y17,"NI")>0),"","!") | Z18: =IF(AND(COUNTIF(Z6:Z17,"FI")>0,COUNTIF(Z6:Z17,"SI")>0,COUNTIF(Z6:Z17,"NI")>0),"","!") | AE18: =IF(AND(COUNTIF(AE6:AE17,"FI")>0,COUNTIF(AE6:AE17,"SI")>0,COUNTIF(AE6:AE17,"NI")>0),"","!") | AF18: =IF(AND(COUNTIF(AF6:AF17,"FI")>0,COUNTIF(AF6:AF17,"SI")>0,COUNTIF(AF6:AF17,"NI")>0),"","!")
A20: Legende | P20: Unterschriften
A21: U | D21: Urlaub | H21: FII 06:00-14:00 | K21: Frühschicht II | P21: Erstellt von:
A22: EH 08:00-17:00 | D22: Erste Hilfe | H22: SI 14:00-22:00 | K22: Spätschicht I
A23: KU 08:30-16:30 | D23: Kuppenheim | H23: SII 14:00-21:00 | K23: Spätschicht II | P23: Datum / Unterschrift
A24: A | D24: AU | H24: NI 22:00-06:00 | K24: Nachtschicht I
A25: GT | D25: Gleittag | H25: DI 08:00-15:30 | K25: Dienst I | P25: Genehmigt von:
A26: NST | D26: Ausgleichstag | H26: DII 08:30-16:00 | K26: Dienst II
A27: Fobi | D27: Fortbildung | H27: KT IRTAZ | K27: Koordination | P27: Datum / Unterschrift
A28: FI 06:00-14:00 | D28: Frühschicht I | H28: SD Individuell | K28: Sonderdienst
D29: Wochenende / Feiertag

Sheet April
A1: Dienstplan April 2027 | AB1: AT: 22 Sa: 4
B2: Osterferien
A3: Tag | B3: 1 | C3: 2 | D3: 3 | E3: 4 | F3: 5 | G3: 6 | H3: 7 | I3: 8 | J3: 9 | K3: 10 | L3: 11 | M3: 12 | N3: 13 | O3: 14 | P3: 15 | Q3: 16 | R3: 17 | S3: 18 | T3: 19 | U3: 20 | V3: 21 | W3: 22 | X3: 23 | Y3: 24 | Z3: 25 | AA3: 26 | AB3: 27 | AC3: 28 | AD3: 29 | AE3: 30
A4: WT | B4: Do | C4: Fr | D4: Sa | E4: So | F4: Mo | G4: Di | H4: Mi | I4: Do | J4: Fr | K4: Sa | L4: So | M4: Mo | N4: Di | O4: Mi | P4: Do | Q4: Fr | R4: Sa | S4: So | T4: Mo | U4: Di | V4: Mi | W4: Do | X4: Fr | Y4: Sa | Z4: So | AA4: Mo | AB4: Di | AC4: Mi | AD4: Do | AE4: Fr
A5: KW | B5: 13 | F5: 14 | M5: 15 | T5: 16 | AA5: 17
A6: Breig | B6: =IF(Dienstplan!B64="","",Dienstplan!B64) | C6: =IF(Dienstplan!C64="","",Dienstplan!C64) | D6: =IF(Dienstplan!D64="","",Dienstplan!D64) | E6: =IF(Dienstplan!E64="","",Dienstplan!E64) | F6: =IF(Dienstplan!F64="","",Dienstplan!F64) | G6: =IF(Dienstplan!G64="","",Dienstplan!G64) | H6: =IF(Dienstplan!H64="","",Dienstplan!H64) | I6: =IF(Dienstplan!I64="","",Dienstplan!I64) | ... AE6: =IF(Dienstplan!AE64="","",Dienstplan!AE64)
A7: Siebert | B7: =IF(Dienstplan!B65="","",Dienstplan!B65) | C7: =IF(Dienstplan!C65="","",Dienstplan!C65) | D7: =IF(Dienstplan!D65="","",Dienstplan!D65) | E7: =IF(Dienstplan!E65="","",Dienstplan!E65) | F7: =IF(Dienstplan!F65="","",Dienstplan!F65) | G7: =IF(Dienstplan!G65="","",Dienstplan!G65) | H7: =IF(Dienstplan!H65="","",Dienstplan!H65) | I7: =IF(Dienstplan!I65="","",Dienstplan!I65) | ... AE7: =IF(Dienstplan!AE65="","",Dienstplan!AE65)
A8: Jochim | B8: =IF(Dienstplan!B66="","",Dienstplan!B66) | C8: =IF(Dienstplan!C66="","",Dienstplan!C66) | D8: =IF(Dienstplan!D66="","",Dienstplan!D66) | E8: =IF(Dienstplan!E66="","",Dienstplan!E66) | F8: =IF(Dienstplan!F66="","",Dienstplan!F66) | G8: =IF(Dienstplan!G66="","",Dienstplan!G66) | H8: =IF(Dienstplan!H66="","",Dienstplan!H66) | I8: =IF(Dienstplan!I66="","",Dienstplan!I66) | ... AE8: =IF(Dienstplan!AE66="","",Dienstplan!AE66)
A9: Wunsch | B9: =IF(Dienstplan!B67="","",Dienstplan!B67) | C9: =IF(Dienstplan!C67="","",Dienstplan!C67) | D9: =IF(Dienstplan!D67="","",Dienstplan!D67) | E9: =IF(Dienstplan!E67="","",Dienstplan!E67) | F9: =IF(Dienstplan!F67="","",Dienstplan!F67) | G9: =IF(Dienstplan!G67="","",Dienstplan!G67) | H9: =IF(Dienstplan!H67="","",Dienstplan!H67) | I9: =IF(Dienstplan!I67="","",Dienstplan!I67) | ... AE9: =IF(Dienstplan!AE67="","",Dienstplan!AE67)
A10: Göpfrich | B10: =IF(Dienstplan!B68="","",Dienstplan!B68) | C10: =IF(Dienstplan!C68="","",Dienstplan!C68) | D10: =IF(Dienstplan!D68="","",Dienstplan!D68) | E10: =IF(Dienstplan!E68="","",Dienstplan!E68) | F10: =IF(Dienstplan!F68="","",Dienstplan!F68) | G10: =IF(Dienstplan!G68="","",Dienstplan!G68) | H10: =IF(Dienstplan!H68="","",Dienstplan!H68) | I10: =IF(Dienstplan!I68="","",Dienstplan!I68) | ... AE10: =IF(Dienstplan!AE68="","",Dienstplan!AE68)
A11: Zeller | B11: =IF(Dienstplan!B69="","",Dienstplan!B69) | C11: =IF(Dienstplan!C69="","",Dienstplan!C69) | D11: =IF(Dienstplan!D69="","",Dienstplan!D69) | E11: =IF(Dienstplan!E69="","",Dienstplan!E69) | F11: =IF(Dienstplan!F69="","",Dienstplan!F69) | G11: =IF(Dienstplan!G69="","",Dienstplan!G69) | H11: =IF(Dienstplan!H69="","",Dienstplan!H69) | I11: =IF(Dienstplan!I69="","",Dienstplan!I69) | ... AE11: =IF(Dienstplan!AE69="","",Dienstplan!AE69)
A12: Behrendt | B12: =IF(Dienstplan!B70="","",Dienstplan!B70) | C12: =IF(Dienstplan!C70="","",Dienstplan!C70) | D12: =IF(Dienstplan!D70="","",Dienstplan!D70) | E12: =IF(Dienstplan!E70="","",Dienstplan!E70) | F12: =IF(Dienstplan!F70="","",Dienstplan!F70) | G12: =IF(Dienstplan!G70="","",Dienstplan!G70) | H12: =IF(Dienstplan!H70="","",Dienstplan!H70) | I12: =IF(Dienstplan!I70="","",Dienstplan!I70) | ... AE12: =IF(Dienstplan!AE70="","",Dienstplan!AE70)
A13: Krempl | B13: =IF(Dienstplan!B71="","",Dienstplan!B71) | C13: =IF(Dienstplan!C71="","",Dienstplan!C71) | D13: =IF(Dienstplan!D71="","",Dienstplan!D71) | E13: =IF(Dienstplan!E71="","",Dienstplan!E71) | F13: =IF(Dienstplan!F71="","",Dienstplan!F71) | G13: =IF(Dienstplan!G71="","",Dienstplan!G71) | H13: =IF(Dienstplan!H71="","",Dienstplan!H71) | I13: =IF(Dienstplan!I71="","",Dienstplan!I71) | ... AE13: =IF(Dienstplan!AE71="","",Dienstplan!AE71)
A14: Putschler | B14: =IF(Dienstplan!B72="","",Dienstplan!B72) | C14: =IF(Dienstplan!C72="","",Dienstplan!C72) | D14: =IF(Dienstplan!D72="","",Dienstplan!D72) | E14: =IF(Dienstplan!E72="","",Dienstplan!E72) | F14: =IF(Dienstplan!F72="","",Dienstplan!F72) | G14: =IF(Dienstplan!G72="","",Dienstplan!G72) | H14: =IF(Dienstplan!H72="","",Dienstplan!H72) | I14: =IF(Dienstplan!I72="","",Dienstplan!I72) | ... AE14: =IF(Dienstplan!AE72="","",Dienstplan!AE72)
A15: Kunz | B15: =IF(Dienstplan!B73="","",Dienstplan!B73) | C15: =IF(Dienstplan!C73="","",Dienstplan!C73) | D15: =IF(Dienstplan!D73="","",Dienstplan!D73) | E15: =IF(Dienstplan!E73="","",Dienstplan!E73) | F15: =IF(Dienstplan!F73="","",Dienstplan!F73) | G15: =IF(Dienstplan!G73="","",Dienstplan!G73) | H15: =IF(Dienstplan!H73="","",Dienstplan!H73) | I15: =IF(Dienstplan!I73="","",Dienstplan!I73) | ... AE15: =IF(Dienstplan!AE73="","",Dienstplan!AE73)
A16: Schmidt | B16: =IF(Dienstplan!B74="","",Dienstplan!B74) | C16: =IF(Dienstplan!C74="","",Dienstplan!C74) | D16: =IF(Dienstplan!D74="","",Dienstplan!D74) | E16: =IF(Dienstplan!E74="","",Dienstplan!E74) | F16: =IF(Dienstplan!F74="","",Dienstplan!F74) | G16: =IF(Dienstplan!G74="","",Dienstplan!G74) | H16: =IF(Dienstplan!H74="","",Dienstplan!H74) | I16: =IF(Dienstplan!I74="","",Dienstplan!I74) | ... AE16: =IF(Dienstplan!AE74="","",Dienstplan!AE74)
A17: Radimersky | B17: =IF(Dienstplan!B75="","",Dienstplan!B75) | C17: =IF(Dienstplan!C75="","",Dienstplan!C75) | D17: =IF(Dienstplan!D75="","",Dienstplan!D75) | E17: =IF(Dienstplan!E75="","",Dienstplan!E75) | F17: =IF(Dienstplan!F75="","",Dienstplan!F75) | G17: =IF(Dienstplan!G75="","",Dienstplan!G75) | H17: =IF(Dienstplan!H75="","",Dienstplan!H75) | I17: =IF(Dienstplan!I75="","",Dienstplan!I75) | ... AE17: =IF(Dienstplan!AE75="","",Dienstplan!AE75)
A18: Besetzung | B18: =IF(AND(COUNTIF(B6:B17,"FI")>0,COUNTIF(B6:B17,"SI")>0,COUNTIF(B6:B17,"NI")>0),"","!") | C18: =IF(AND(COUNTIF(C6:C17,"FI")>0,COUNTIF(C6:C17,"SI")>0),"","!") | F18: =IF(AND(COUNTIF(F6:F17,"FI")>0,COUNTIF(F6:F17,"SI")>0,COUNTIF(F6:F17,"NI")>0),"","!") | G18: =IF(AND(COUNTIF(G6:G17,"FI")>0,COUNTIF(G6:G17,"SI")>0,COUNTIF(G6:G17,"NI")>0),"","!") | H18: =IF(AND(COUNTIF(H6:H17,"FI")>0,COUNTIF(H6:H17,"SI")>0,COUNTIF(H6:H17,"NI")>0),"","!") | I18: =IF(AND(COUNTIF(I6:I17,"FI")>0,COUNTIF(I6:I17,"SI")>0,COUNTIF(I6:I17,"NI")>0),"","!") | J18: =IF(AND(COUNTIF(J6:J17,"FI")>0,COUNTIF(J6:J17,"SI")>0),"","!") | M18: =IF(AND(COUNTIF(M6:M17,"FI")>0,COUNTIF(M6:M17,"SI")>0,COUNTIF(M6:M17,"NI")>0),"","!") | N18: =IF(AND(COUNTIF(N6:N17,"FI")>0,COUNTIF(N6:N17,"SI")>0,COUNTIF(N6:N17,"NI")>0),"","!") | O18: =IF(AND(COUNTIF(O6:O17,"FI")>0,COUNTIF(O6:O17,"SI")>0,COUNTIF(O6:O17,"NI")>0),"","!") | P18: =IF(AND(COUNTIF(P6:P17,"FI")>0,COUNTIF(P6:P17,"SI")>0,COUNTIF(P6:P17,"NI")>0),"","!") | Q18: =IF(AND(COUNTIF(Q6:Q17,"FI")>0,COUNTIF(Q6:Q17,"SI")>0),"","!") | T18: =IF(AND(COUNTIF(T6:T17,"FI")>0,COUNTIF(T6:T17,"SI")>0,COUNTIF(T6:T17,"NI")>0),"","!") | U18: =IF(AND(COUNTIF(U6:U17,"FI")>0,COUNTIF(U6:U17,"SI")>0,COUNTIF(U6:U17,"NI")>0),"","!") | V18: =IF(AND(COUNTIF(V6:V17,"FI")>0,COUNTIF(V6:V17,"SI")>0,COUNTIF(V6:V17,"NI")>0),"","!") | W18: =IF(AND(COUNTIF(W6:W17,"FI")>0,COUNTIF(W6:W17,"SI")>0,COUNTIF(W6:W17,"NI")>0),"","!") | X18: =IF(AND(COUNTIF(X6:X17,"FI")>0,COUNTIF(X6:X17,"SI")>0),"","!") | AA18: =IF(AND(COUNTIF(AA6:AA17,"FI")>0,COUNTIF(AA6:AA17,"SI")>0,COUNTIF(AA6:AA17,"NI")>0),"","!") | AB18: =IF(AND(COUNTIF(AB6:AB17,"FI")>0,COUNTIF(AB6:AB17,"SI")>0,COUNTIF(AB6:AB17,"NI")>0),"","!") | AC18: =IF(AND(COUNTIF(AC6:AC17,"FI")>0,COUNTIF(AC6:AC17,"SI")>0,COUNTIF(AC6:AC17,"NI")>0),"","!") | AD18: =IF(AND(COUNTIF(AD6:AD17,"FI")>0,COUNTIF(AD6:AD17,"SI")>0,COUNTIF(AD6:AD17,"NI")>0),"","!") | AE18: =IF(AND(COUNTIF(AE6:AE17,"FI")>0,COUNTIF(AE6:AE17,"SI")>0),"","!")
A20: Legende | P20: Unterschriften
A21: U | D21: Urlaub | H21: FII 06:00-14:00 | K21: Frühschicht II | P21: Erstellt von:
A22: EH 08:00-17:00 | D22: Erste Hilfe | H22: SI 14:00-22:00 | K22: Spätschicht I
A23: KU 08:30-16:30 | D23: Kuppenheim | H23: SII 14:00-21:00 | K23: Spätschicht II | P23: Datum / Unterschrift
A24: A | D24: AU | H24: NI 22:00-06:00 | K24: Nachtschicht I
A25: GT | D25: Gleittag | H25: DI 08:00-15:30 | K25: Dienst I | P25: Genehmigt von:
A26: NST | D26: Ausgleichstag | H26: DII 08:30-16:00 | K26: Dienst II
A27: Fobi | D27: Fortbildung | H27: KT IRTAZ | K27: Koordination | P27: Datum / Unterschrift
A28: FI 06:00-14:00 | D28: Frühschicht I | H28: SD Individuell | K28: Sonderdienst
D29: Wochenende / Feiertag

Sheet Mai
A1: Dienstplan Mai 2027 | AC1: AT: 18 Sa: 5
R2: Pfingstferien
A3: Tag | B3: 1 | C3: 2 | D3: 3 | E3: 4 | F3: 5 | G3: 6 | H3: 7 | I3: 8 | J3: 9 | K3: 10 | L3: 11 | M3: 12 | N3: 13 | O3: 14 | P3: 15 | Q3: 16 | R3: 17 | S3: 18 | T3: 19 | U3: 20 | V3: 21 | W3: 22 | X3: 23 | Y3: 24 | Z3: 25 | AA3: 26 | AB3: 27 | AC3: 28 | AD3: 29 | AE3: 30 | AF3: 31
A4: WT | B4: Sa | C4: So | D4: Mo | E4: Di | F4: Mi | G4: Do | H4: Fr | I4: Sa | J4: So | K4: Mo | L4: Di | M4: Mi | N4: Do | O4: Fr | P4: Sa | Q4: So | R4: Mo | S4: Di | T4: Mi | U4: Do | V4: Fr | W4: Sa | X4: So | Y4: Mo | Z4: Di | AA4: Mi | AB4: Do | AC4: Fr | AD4: Sa | AE4: So | AF4: Mo
A5: KW | B5: 17 | D5: 18 | K5: 19 | R5: 20 | Y5: 21 | AF5: 22
A6: Breig | B6: =IF(Dienstplan!B83="","",Dienstplan!B83) | C6: =IF(Dienstplan!C83="","",Dienstplan!C83) | D6: =IF(Dienstplan!D83="","",Dienstplan!D83) | E6: =IF(Dienstplan!E83="","",Dienstplan!E83) | F6: =IF(Dienstplan!F83="","",Dienstplan!F83) | G6: =IF(Dienstplan!G83="","",Dienstplan!G83) | H6: =IF(Dienstplan!H83="","",Dienstplan!H83) | I6: =IF(Dienstplan!I83="","",Dienstplan!I83) | ... AF6: =IF(Dienstplan!AF83="","",Dienstplan!AF83)
A7: Siebert | B7: =IF(Dienstplan!B84="","",Dienstplan!B84) | C7: =IF(Dienstplan!C84="","",Dienstplan!C84) | D7: =IF(Dienstplan!D84="","",Dienstplan!D84) | E7: =IF(Dienstplan!E84="","",Dienstplan!E84) | F7: =IF(Dienstplan!F84="","",Dienstplan!F84) | G7: =IF(Dienstplan!G84="","",Dienstplan!G84) | H7: =IF(Dienstplan!H84="","",Dienstplan!H84) | I7: =IF(Dienstplan!I84="","",Dienstplan!I84) | ... AF7: =IF(Dienstplan!AF84="","",Dienstplan!AF84)
A8: Jochim | B8: =IF(Dienstplan!B85="","",Dienstplan!B85) | C8: =IF(Dienstplan!C85="","",Dienstplan!C85) | D8: =IF(Dienstplan!D85="","",Dienstplan!D85) | E8: =IF(Dienstplan!E85="","",Dienstplan!E85) | F8: =IF(Dienstplan!F85="","",Dienstplan!F85) | G8: =IF(Dienstplan!G85="","",Dienstplan!G85) | H8: =IF(Dienstplan!H85="","",Dienstplan!H85) | I8: =IF(Dienstplan!I85="","",Dienstplan!I85) | ... AF8: =IF(Dienstplan!AF85="","",Dienstplan!AF85)
A9: Wunsch | B9: =IF(Dienstplan!B86="","",Dienstplan!B86) | C9: =IF(Dienstplan!C86="","",Dienstplan!C86) | D9: =IF(Dienstplan!D86="","",Dienstplan!D86) | E9: =IF(Dienstplan!E86="","",Dienstplan!E86) | F9: =IF(Dienstplan!F86="","",Dienstplan!F86) | G9: =IF(Dienstplan!G86="","",Dienstplan!G86) | H9: =IF(Dienstplan!H86="","",Dienstplan!H86) | I9: =IF(Dienstplan!I86="","",Dienstplan!I86) | ... AF9: =IF(Dienstplan!AF86="","",Dienstplan!AF86)
A10: Göpfrich | B10: =IF(Dienstplan!B87="","",Dienstplan!B87) | C10: =IF(Dienstplan!C87="","",Dienstplan!C87) | D10: =IF(Dienstplan!D87="","",Dienstplan!D87) | E10: =IF(Dienstplan!E87="","",Dienstplan!E87) | F10: =IF(Dienstplan!F87="","",Dienstplan!F87) | G10: =IF(Dienstplan!G87="","",Dienstplan!G87) | H10: =IF(Dienstplan!H87="","",Dienstplan!H87) | I10: =IF(Dienstplan!I87="","",Dienstplan!I87) | ... AF10: =IF(Dienstplan!AF87="","",Dienstplan!AF87)
A11: Zeller | B11: =IF(Dienstplan!B88="","",Dienstplan!B88) | C11: =IF(Dienstplan!C88="","",Dienstplan!C88) | D11: =IF(Dienstplan!D88="","",Dienstplan!D88) | E11: =IF(Dienstplan!E88="","",Dienstplan!E88) | F11: =IF(Dienstplan!F88="","",Dienstplan!F88) | G11: =IF(Dienstplan!G88="","",Dienstplan!G88) | H11: =IF(Dienstplan!H88="","",Dienstplan!H88) | I11: =IF(Dienstplan!I88="","",Dienstplan!I88) | ... AF11: =IF(Dienstplan!AF88="","",Dienstplan!AF88)
A12: Behrendt | B12: =IF(Dienstplan!B89="","",Dienstplan!B89) | C12: =IF(Dienstplan!C89="","",Dienstplan!C89) | D12: =IF(Dienstplan!D89="","",Dienstplan!D89) | E12: =IF(Dienstplan!E89="","",Dienstplan!E89) | F12: =IF(Dienstplan!F89="","",Dienstplan!F89) | G12: =IF(Dienstplan!G89="","",Dienstplan!G89) | H12: =IF(Dienstplan!H89="","",Dienstplan!H89) | I12: =IF(Dienstplan!I89="","",Dienstplan!I89) | ... AF12: =IF(Dienstplan!AF89="","",Dienstplan!AF89)
A13: Krempl | B13: =IF(Dienstplan!B90="","",Dienstplan!B90) | C13: =IF(Dienstplan!C90="","",Dienstplan!C90) | D13: =IF(Dienstplan!D90="","",Dienstplan!D90) | E13: =IF(Dienstplan!E90="","",Dienstplan!E90) | F13: =IF(Dienstplan!F90="","",Dienstplan!F90) | G13: =IF(Dienstplan!G90="","",Dienstplan!G90) | H13: =IF(Dienstplan!H90="","",Dienstplan!H90) | I13: =IF(Dienstplan!I90="","",Dienstplan!I90) | ... AF13: =IF(Dienstplan!AF90="","",Dienstplan!AF90)
A14: Putschler | B14: =IF(Dienstplan!B91="","",Dienstplan!B91) | C14: =IF(Dienstplan!C91="","",Dienstplan!C91) | D14: =IF(Dienstplan!D91="","",Dienstplan!D91) | E14: =IF(Dienstplan!E91="","",Dienstplan!E91) | F14: =IF(Dienstplan!F91="","",Dienstplan!F91) | G14: =IF(Dienstplan!G91="","",Dienstplan!G91) | H14: =IF(Dienstplan!H91="","",Dienstplan!H91) | I14: =IF(Dienstplan!I91="","",Dienstplan!I91) | ... AF14: =IF(Dienstplan!AF91="","",Dienstplan!AF91)
A15: Kunz | B15: =IF(Dienstplan!B92="","",Dienstplan!B92) | C15: =IF(Dienstplan!C92="","",Dienstplan!C92) | D15: =IF(Dienstplan!D92="","",Dienstplan!D92) | E15: =IF(Dienstplan!E92="","",Dienstplan!E92) | F15: =IF(Dienstplan!F92="","",Dienstplan!F92) | G15: =IF(Dienstplan!G92="","",Dienstplan!G92) | H15: =IF(Dienstplan!H92="","",Dienstplan!H92) | I15: =IF(Dienstplan!I92="","",Dienstplan!I92) | ... AF15: =IF(Dienstplan!AF92="","",Dienstplan!AF92)
A16: Schmidt | B16: =IF(Dienstplan!B93="","",Dienstplan!B93) | C16: =IF(Dienstplan!C93="","",Dienstplan!C93) | D16: =IF(Dienstplan!D93="","",Dienstplan!D93) | E16: =IF(Dienstplan!E93="","",Dienstplan!E93) | F16: =IF(Dienstplan!F93="","",Dienstplan!F93) | G16: =IF(Dienstplan!G93="","",Dienstplan!G93) | H16: =IF(Dienstplan!H93="","",Dienstplan!H93) | I16: =IF(Dienstplan!I93="","",Dienstplan!I93) | ... AF16: =IF(Dienstplan!AF93="","",Dienstplan!AF93)
A17: Radimersky | B17: =IF(Dienstplan!B94="","",Dienstplan!B94) | C17: =IF(Dienstplan!C94="","",Dienstplan!C94) | D17: =IF(Dienstplan!D94="","",Dienstplan!D94) | E17: =IF(Dienstplan!E94="","",Dienstplan!E94) | F17: =IF(Dienstplan!F94="","",Dienstplan!F94) | G17: =IF(Dienstplan!G94="","",Dienstplan!G94) | H17: =IF(Dienstplan!H94="","",Dienstplan!H94) | I17: =IF(Dienstplan!I94="","",Dienstplan!I94) | ... AF17: =IF(Dienstplan!AF94="","",Dienstplan!AF94)
A18: Besetzung | D18: =IF(AND(COUNTIF(D6:D17,"FI")>0,COUNTIF(D6:D17,"SI")>0,COUNTIF(D6:D17,"NI")>0),"","!") | E18: =IF(AND(COUNTIF(E6:E17,"FI")>0,COUNTIF(E6:E17,"SI")>0,COUNTIF(E6:E17,"NI")>0),"","!") | F18: =IF(AND(COUNTIF(F6:F17,"FI")>0,COUNTIF(F6:F17,"SI")>0,COUNTIF(F6:F17,"NI")>0),"","!") | H18: =IF(AND(COUNTIF(H6:H17,"FI")>0,COUNTIF(H6:H17,"SI")>0),"","!") | K18: =IF(AND(COUNTIF(K6:K17,"FI")>0,COUNTIF(K6:K17,"SI")>0,COUNTIF(K6:K17,"NI")>0),"","!") | L18: =IF(AND(COUNTIF(L6:L17,"FI")>0,COUNTIF(L6:L17,"SI")>0,COUNTIF(L6:L17,"NI")>0),"","!") | M18: =IF(AND(COUNTIF(M6:M17,"FI")>0,COUNTIF(M6:M17,"SI")>0,COUNTIF(M6:M17,"NI")>0),"","!") | N18: =IF(AND(COUNTIF(N6:N17,"FI")>0,COUNTIF(N6:N17,"SI")>0,COUNTIF(N6:N17,"NI")>0),"","!") | O18: =IF(AND(COUNTIF(O6:O17,"FI")>0,COUNTIF(O6:O17,"SI")>0),"","!") | S18: =IF(AND(COUNTIF(S6:S17,"FI")>0,COUNTIF(S6:S17,"SI")>0,COUNTIF(S6:S17,"NI")>0),"","!") | T18: =IF(AND(COUNTIF(T6:T17,"FI")>0,COUNTIF(T6:T17,"SI")>0,COUNTIF(T6:T17,"NI")>0),"","!") | U18: =IF(AND(COUNTIF(U6:U17,"FI")>0,COUNTIF(U6:U17,"SI")>0,COUNTIF(U6:U17,"NI")>0),"","!") | V18: =IF(AND(COUNTIF(V6:V17,"FI")>0,COUNTIF(V6:V17,"SI")>0),"","!") | Y18: =IF(AND(COUNTIF(Y6:Y17,"FI")>0,COUNTIF(Y6:Y17,"SI")>0,COUNTIF(Y6:Y17,"NI")>0),"","!") | Z18: =IF(AND(COUNTIF(Z6:Z17,"FI")>0,COUNTIF(Z6:Z17,"SI")>0,COUNTIF(Z6:Z17,"NI")>0),"","!") | AA18: =IF(AND(COUNTIF(AA6:AA17,"FI")>0,COUNTIF(AA6:AA17,"SI")>0,COUNTIF(AA6:AA17,"NI")>0),"","!") | AC18: =IF(AND(COUNTIF(AC6:AC17,"FI")>0,COUNTIF(AC6:AC17,"SI")>0),"","!") | AF18: =IF(AND(COUNTIF(AF6:AF17,"FI")>0,COUNTIF(AF6:AF17,"SI")>0,COUNTIF(AF6:AF17,"NI")>0),"","!")
A20: Legende | P20: Unterschriften
A21: U | D21: Urlaub | H21: FII 06:00-14:00 | K21: Frühschicht II | P21: Erstellt von:
A22: EH 08:00-17:00 | D22: Erste Hilfe | H22: SI 14:00-22:00 | K22: Spätschicht I
A23: KU 08:30-16:30 | D23: Kuppenheim | H23: SII 14:00-21:00 | K23: Spätschicht II | P23: Datum / Unterschrift
A24: A | D24: AU | H24: NI 22:00-06:00 | K24: Nachtschicht I
A25: GT | D25: Gleittag | H25: DI 08:00-15:30 | K25: Dienst I | P25: Genehmigt von:
A26: NST | D26: Ausgleichstag | H26: DII 08:30-16:00 | K26: Dienst II
A27: Fobi | D27: Fortbildung | H27: KT IRTAZ | K27: Koordination | P27: Datum / Unterschrift
A28: FI 06:00-14:00 | D28: Frühschicht I | H28: SD Individuell | K28: Sonderdienst
D29: Wochenende / Feiertag

Sheet Juni
A1: Dienstplan Juni 2027 | AB1: AT: 22 Sa: 4
A3: Tag | B3: 1 | C3: 2 | D3: 3 | E3: 4 | F3: 5 | G3: 6 | H3: 7 | I3: 8 | J3: 9 | K3: 10 | L3: 11 | M3: 12 | N3: 13 | O3: 14 | P3: 15 | Q3: 16 | R3: 17 | S3: 18 | T3: 19 | U3: 20 | V3: 21 | W3: 22 | X3: 23 | Y3: 24 | Z3: 25 | AA3: 26 | AB3: 27 | AC3: 28 | AD3: 29 | AE3: 30
A4: WT | B4: Di | C4: Mi | D4: Do | E4: Fr | F4: Sa | G4: So | H4: Mo | I4: Di | J4: Mi | K4: Do | L4: Fr | M4: Sa | N4: So | O4: Mo | P4: Di | Q4: Mi | R4: Do | S4: Fr | T4: Sa | U4: So | V4: Mo | W4: Di | X4: Mi | Y4: Do | Z4: Fr | AA4: Sa | AB4: So | AC4: Mo | AD4: Di | AE4: Mi
A5: KW | B5: 22 | H5: 23 | O5: 24 | V5: 25 | AC5: 26
A6: Breig | B6: =IF(Dienstplan!B101="","",Dienstplan!B101) | C6: =IF(Dienstplan!C101="","",Dienstplan!C101) | D6: =IF(Dienstplan!D101="","",Dienstplan!D101) | E6: =IF(Dienstplan!E101="","",Dienstplan!E101) | F6: =IF(Dienstplan!F101="","",Dienstplan!F101) | G6: =IF(Dienstplan!G101="","",Dienstplan!G101) | H6: =IF(Dienstplan!H101="","",Dienstplan!H101) | I6: =IF(Dienstplan!I101="","",Dienstplan!I101) | ... AE6: =IF(Dienstplan!AE101="","",Dienstplan!AE101)
A7: Siebert | B7: =IF(Dienstplan!B102="","",Dienstplan!B102) | C7: =IF(Dienstplan!C102="","",Dienstplan!C102) | D7: =IF(Dienstplan!D102="","",Dienstplan!D102) | E7: =IF(Dienstplan!E102="","",Dienstplan!E102) | F7: =IF(Dienstplan!F102="","",Dienstplan!F102) | G7: =IF(Dienstplan!G102="","",Dienstplan!G102) | H7: =IF(Dienstplan!H102="","",Dienstplan!H102) | I7: =IF(Dienstplan!I102="","",Dienstplan!I102) | ... AE7: =IF(Dienstplan!AE102="","",Dienstplan!AE102)
A8: Jochim | B8: =IF(Dienstplan!B103="","",Dienstplan!B103) | C8: =IF(Dienstplan!C103="","",Dienstplan!C103) | D8: =IF(Dienstplan!D103="","",Dienstplan!D103) | E8: =IF(Dienstplan!E103="","",Dienstplan!E103) | F8: =IF(Dienstplan!F103="","",Dienstplan!F103) | G8: =IF(Dienstplan!G103="","",Dienstplan!G103) | H8: =IF(Dienstplan!H103="","",Dienstplan!H103) | I8: =IF(Dienstplan!I103="","",Dienstplan!I103) | ... AE8: =IF(Dienstplan!AE103="","",Dienstplan!AE103)
A9: Wunsch | B9: =IF(Dienstplan!B104="","",Dienstplan!B104) | C9: =IF(Dienstplan!C104="","",Dienstplan!C104) | D9: =IF(Dienstplan!D104="","",Dienstplan!D104) | E9: =IF(Dienstplan!E104="","",Dienstplan!E104) | F9: =IF(Dienstplan!F104="","",Dienstplan!F104) | G9: =IF(Dienstplan!G104="","",Dienstplan!G104) | H9: =IF(Dienstplan!H104="","",Dienstplan!H104) | I9: =IF(Dienstplan!I104="","",Dienstplan!I104) | ... AE9: =IF(Dienstplan!AE104="","",Dienstplan!AE104)
A10: Göpfrich | B10: =IF(Dienstplan!B105="","",Dienstplan!B105) | C10: =IF(Dienstplan!C105="","",Dienstplan!C105) | D10: =IF(Dienstplan!D105="","",Dienstplan!D105) | E10: =IF(Dienstplan!E105="","",Dienstplan!E105) | F10: =IF(Dienstplan!F105="","",Dienstplan!F105) | G10: =IF(Dienstplan!G105="","",Dienstplan!G105) | H10: =IF(Dienstplan!H105="","",Dienstplan!H105) | I10: =IF(Dienstplan!I105="","",Dienstplan!I105) | ... AE10: =IF(Dienstplan!AE105="","",Dienstplan!AE105)
A11: Zeller | B11: =IF(Dienstplan!B106="","",Dienstplan!B106) | C11: =IF(Dienstplan!C106="","",Dienstplan!C106) | D11: =IF(Dienstplan!D106="","",Dienstplan!D106) | E11: =IF(Dienstplan!E106="","",Dienstplan!E106) | F11: =IF(Dienstplan!F106="","",Dienstplan!F106) | G11: =IF(Dienstplan!G106="","",Dienstplan!G106) | H11: =IF(Dienstplan!H106="","",Dienstplan!H106) | I11: =IF(Dienstplan!I106="","",Dienstplan!I106) | ... AE11: =IF(Dienstplan!AE106="","",Dienstplan!AE106)
A12: Behrendt | B12: =IF(Dienstplan!B107="","",Dienstplan!B107) | C12: =IF(Dienstplan!C107="","",Dienstplan!C107) | D12: =IF(Dienstplan!D107="","",Dienstplan!D107) | E12: =IF(Dienstplan!E107="","",Dienstplan!E107) | F12: =IF(Dienstplan!F107="","",Dienstplan!F107) | G12: =IF(Dienstplan!G107="","",Dienstplan!G107) | H12: =IF(Dienstplan!H107="","",Dienstplan!H107) | I12: =IF(Dienstplan!I107="","",Dienstplan!I107) | ... AE12: =IF(Dienstplan!AE107="","",Dienstplan!AE107)
A13: Krempl | B13: =IF(Dienstplan!B108="","",Dienstplan!B108) | C13: =IF(Dienstplan!C108="","",Dienstplan!C108) | D13: =IF(Dienstplan!D108="","",Dienstplan!D108) | E13: =IF(Dienstplan!E108="","",Dienstplan!E108) | F13: =IF(Dienstplan!F108="","",Dienstplan!F108) | G13: =IF(Dienstplan!G108="","",Dienstplan!G108) | H13: =IF(Dienstplan!H108="","",Dienstplan!H108) | I13: =IF(Dienstplan!I108="","",Dienstplan!I108) | ... AE13: =IF(Dienstplan!AE108="","",Dienstplan!AE108)
A14: Putschler | B14: =IF(Dienstplan!B109="","",Dienstplan!B109) | C14: =IF(Dienstplan!C109="","",Dienstplan!C109) | D14: =IF(Dienstplan!D109="","",Dienstplan!D109) | E14: =IF(Dienstplan!E109="","",Dienstplan!E109) | F14: =IF(Dienstplan!F109="","",Dienstplan!F109) | G14: =IF(Dienstplan!G109="","",Dienstplan!G109) | H14: =IF(Dienstplan!H109="","",Dienstplan!H109) | I14: =IF(Dienstplan!I109="","",Dienstplan!I109) | ... AE14: =IF(Dienstplan!AE109="","",Dienstplan!AE109)
A15: Kunz | B15: =IF(Dienstplan!B110="","",Dienstplan!B110) | C15: =IF(Dienstplan!C110="","",Dienstplan!C110) | D15: =IF(Dienstplan!D110="","",Dienstplan!D110) | E15: =IF(Dienstplan!E110="","",Dienstplan!E110) | F15: =IF(Dienstplan!F110="","",Dienstplan!F110) | G15: =IF(Dienstplan!G110="","",Dienstplan!G110) | H15: =IF(Dienstplan!H110="","",Dienstplan!H110) | I15: =IF(Dienstplan!I110="","",Dienstplan!I110) | ... AE15: =IF(Dienstplan!AE110="","",Dienstplan!AE110)
A16: Schmidt | B16: =IF(Dienstplan!B111="","",Dienstplan!B111) | C16: =IF(Dienstplan!C111="","",Dienstplan!C111) | D16: =IF(Dienstplan!D111="","",Dienstplan!D111) | E16: =IF(Dienstplan!E111="","",Dienstplan!E111) | F16: =IF(Dienstplan!F111="","",Dienstplan!F111) | G16: =IF(Dienstplan!G111="","",Dienstplan!G111) | H16: =IF(Dienstplan!H111="","",Dienstplan!H111) | I16: =IF(Dienstplan!I111="","",Dienstplan!I111) | ... AE16: =IF(Dienstplan!AE111="","",Dienstplan!AE111)
A17: Radimersky | B17: =IF(Dienstplan!B112="","",Dienstplan!B112) | C17: =IF(Dienstplan!C112="","",Dienstplan!C112) | D17: =IF(Dienstplan!D112="","",Dienstplan!D112) | E17: =IF(Dienstplan!E112="","",Dienstplan!E112) | F17: =IF(Dienstplan!F112="","",Dienstplan!F112) | G17: =IF(Dienstplan!G112="","",Dienstplan!G112) | H17: =IF(Dienstplan!H112="","",Dienstplan!H112) | I17: =IF(Dienstplan!I112="","",Dienstplan!I112) | ... AE17: =IF(Dienstplan!AE112="","",Dienstplan!AE112)
A18: Besetzung | B18: =IF(AND(COUNTIF(B6:B17,"FI")>0,COUNTIF(B6:B17,"SI")>0,COUNTIF(B6:B17,"NI")>0),"","!") | C18: =IF(AND(COUNTIF(C6:C17,"FI")>0,COUNTIF(C6:C17,"SI")>0,COUNTIF(C6:C17,"NI")>0),"","!") | D18: =IF(AND(COUNTIF(D6:D17,"FI")>0,COUNTIF(D6:D17,"SI")>0,COUNTIF(D6:D17,"NI")>0),"","!") | E18: =IF(AND(COUNTIF(E6:E17,"FI")>0,COUNTIF(E6:E17,"SI")>0),"","!") | H18: =IF(AND(COUNTIF(H6:H17,"FI")>0,COUNTIF(H6:H17,"SI")>0,COUNTIF(H6:H17,"NI")>0),"","!") | I18: =IF(AND(COUNTIF(I6:I17,"FI")>0,COUNTIF(I6:I17,"SI")>0,COUNTIF(I6:I17,"NI")>0),"","!") | J18: =IF(AND(COUNTIF(J6:J17,"FI")>0,COUNTIF(J6:J17,"SI")>0,COUNTIF(J6:J17,"NI")>0),"","!") | K18: =IF(AND(COUNTIF(K6:K17,"FI")>0,COUNTIF(K6:K17,"SI")>0,COUNTIF(K6:K17,"NI")>0),"","!") | L18: =IF(AND(COUNTIF(L6:L17,"FI")>0,COUNTIF(L6:L17,"SI")>0),"","!") | O18: =IF(AND(COUNTIF(O6:O17,"FI")>0,COUNTIF(O6:O17,"SI")>0,COUNTIF(O6:O17,"NI")>0),"","!") | P18: =IF(AND(COUNTIF(P6:P17,"FI")>0,COUNTIF(P6:P17,"SI")>0,COUNTIF(P6:P17,"NI")>0),"","!") | Q18: =IF(AND(COUNTIF(Q6:Q17,"FI")>0,COUNTIF(Q6:Q17,"SI")>0,COUNTIF(Q6:Q17,"NI")>0),"","!") | R18: =IF(AND(COUNTIF(R6:R17,"FI")>0,COUNTIF(R6:R17,"SI")>0,COUNTIF(R6:R17,"NI")>0),"","!") | S18: =IF(AND(COUNTIF(S6:S17,"FI")>0,COUNTIF(S6:S17,"SI")>0),"","!") | V18: =IF(AND(COUNTIF(V6:V17,"FI")>0,COUNTIF(V6:V17,"SI")>0,COUNTIF(V6:V17,"NI")>0),"","!") | W18: =IF(AND(COUNTIF(W6:W17,"FI")>0,COUNTIF(W6:W17,"SI")>0,COUNTIF(W6:W17,"NI")>0),"","!") | X18: =IF(AND(COUNTIF(X6:X17,"FI")>0,COUNTIF(X6:X17,"SI")>0,COUNTIF(X6:X17,"NI")>0),"","!") | Y18: =IF(AND(COUNTIF(Y6:Y17,"FI")>0,COUNTIF(Y6:Y17,"SI")>0,COUNTIF(Y6:Y17,"NI")>0),"","!") | Z18: =IF(AND(COUNTIF(Z6:Z17,"FI")>0,COUNTIF(Z6:Z17,"SI")>0),"","!") | AC18: =IF(AND(COUNTIF(AC6:AC17,"FI")>0,COUNTIF(AC6:AC17,"SI")>0,COUNTIF(AC6:AC17,"NI")>0),"","!") | AD18: =IF(AND(COUNTIF(AD6:AD17,"FI")>0,COUNTIF(AD6:AD17,"SI")>0,COUNTIF(AD6:AD17,"NI")>0),"","!") | AE18: =IF(AND(COUNTIF(AE6:AE17,"FI")>0,COUNTIF(AE6:AE17,"SI")>0,COUNTIF(AE6:AE17,"NI")>0),"","!")
A20: Legende | P20: Unterschriften
A21: U | D21: Urlaub | H21: FII 06:00-14:00 | K21: Frühschicht II | P21: Erstellt von:
A22: EH 08:00-17:00 | D22: Erste Hilfe | H22: SI 14:00-22:00 | K22: Spätschicht I
A23: KU 08:30-16:30 | D23: Kuppenheim | H23: SII 14:00-21:00 | K23: Spätschicht II | P23: Datum / Unterschrift
A24: A | D24: AU | H24: NI 22:00-06:00 | K24: Nachtschicht I
A25: GT | D25: Gleittag | H25: DI 08:00-15:30 | K25: Dienst I | P25: Genehmigt von:
A26: NST | D26: Ausgleichstag | H26: DII 08:30-16:00 | K26: Dienst II
A27: Fobi | D27: Fortbildung | H27: KT IRTAZ | K27: Koordination | P27: Datum / Unterschrift
A28: FI 06:00-14:00 | D28: Frühschicht I | H28: SD Individuell | K28: Sonderdienst
D29: Wochenende / Feiertag

Sheet Juli
A1: Dienstplan Juli 2027 | AC1: AT: 22 Sa: 5
AE2: Sommerferien
A3: Tag | B3: 1 | C3: 2 | D3: 3 | E3: 4 | F3: 5 | G3: 6 | H3: 7 | I3: 8 | J3: 9 | K3: 10 | L3: 11 | M3: 12 | N3: 13 | O3: 14 | P3: 15 | Q3: 16 | R3: 17 | S3: 18 | T3: 19 | U3: 20 | V3: 21 | W3: 22 | X3: 23 | Y3: 24 | Z3: 25 | AA3: 26 | AB3: 27 | AC3: 28 | AD3: 29 | AE3: 30 | AF3: 31
A4: WT | B4: Do | C4: Fr | D4: Sa | E4: So | F4: Mo | G4: Di | H4: Mi | I4: Do | J4: Fr | K4: Sa | L4: So | M4: Mo | N4: Di | O4: Mi | P4: Do | Q4: Fr | R4: Sa | S4: So | T4: Mo | U4: Di | V4: Mi | W4: Do | X4: Fr | Y4: Sa | Z4: So | AA4: Mo | AB4: Di | AC4: Mi | AD4: Do | AE4: Fr | AF4: Sa
A5: KW | B5: 26 | F5: 27 | M5: 28 | T5: 29 | AA5: 30
A6: Breig | B6: =IF(Dienstplan!B120="","",Dienstplan!B120) | C6: =IF(Dienstplan!C120="","",Dienstplan!C120) | D6: =IF(Dienstplan!D120="","",Dienstplan!D120) | E6: =IF(Dienstplan!E120="","",Dienstplan!E120) | F6: =IF(Dienstplan!F120="","",Dienstplan!F120) | G6: =IF(Dienstplan!G120="","",Dienstplan!G120) | H6: =IF(Dienstplan!H120="","",Dienstplan!H120) | I6: =IF(Dienstplan!I120="","",Dienstplan!I120) | ... AF6: =IF(Dienstplan!AF120="","",Dienstplan!AF120)
A7: Siebert | B7: =IF(Dienstplan!B121="","",Dienstplan!B121) | C7: =IF(Dienstplan!C121="","",Dienstplan!C121) | D7: =IF(Dienstplan!D121="","",Dienstplan!D121) | E7: =IF(Dienstplan!E121="","",Dienstplan!E121) | F7: =IF(Dienstplan!F121="","",Dienstplan!F121) | G7: =IF(Dienstplan!G121="","",Dienstplan!G121) | H7: =IF(Dienstplan!H121="","",Dienstplan!H121) | I7: =IF(Dienstplan!I121="","",Dienstplan!I121) | ... AF7: =IF(Dienstplan!AF121="","",Dienstplan!AF121)
A8: Jochim | B8: =IF(Dienstplan!B122="","",Dienstplan!B122) | C8: =IF(Dienstplan!C122="","",Dienstplan!C122) | D8: =IF(Dienstplan!D122="","",Dienstplan!D122) | E8: =IF(Dienstplan!E122="","",Dienstplan!E122) | F8: =IF(Dienstplan!F122="","",Dienstplan!F122) | G8: =IF(Dienstplan!G122="","",Dienstplan!G122) | H8: =IF(Dienstplan!H122="","",Dienstplan!H122) | I8: =IF(Dienstplan!I122="","",Dienstplan!I122) | ... AF8: =IF(Dienstplan!AF122="","",Dienstplan!AF122)
